Workbook

Sheet Overview
A1: Belanjawan 2027 Fresh Graduate Wage Cost Model
A2: Fully loaded employer cost and employee take-home pay at the three Belanjawan 2027 wage benchmarks.
A4: Headline (RM / month) | B4: National Minimum Wage | C4: Fresh Graduate Floor | D4: GLC / GLIC Living Wage
A5: Gross monthly wage | B5: ='Benchmark Comparison'!B6 | C5: ='Benchmark Comparison'!C6 | D5: ='Benchmark Comparison'!D6
A6: Employer on-costs | B6: ='Benchmark Comparison'!B13 | C6: ='Benchmark Comparison'!C13 | D6: ='Benchmark Comparison'!D13
A7: Fully loaded monthly cost | B7: ='Benchmark Comparison'!B14 | C7: ='Benchmark Comparison'!C14 | D7: ='Benchmark Comparison'!D14
A8: On-costs as % of gross wage | B8: ='Benchmark Comparison'!B15 | C8: ='Benchmark Comparison'!C15 | D8: ='Benchmark Comparison'!D15
A9: Net take-home pay | B9: ='Benchmark Comparison'!B24 | C9: ='Benchmark Comparison'!C24 | D9: ='Benchmark Comparison'!D24
A10: PCB / MTD | B10: ='Benchmark Comparison'!B22 | C10: ='Benchmark Comparison'!C22 | D10: ='Benchmark Comparison'!D22
A11: Fully loaded annual cost | B11: ='Benchmark Comparison'!B16 | C11: ='Benchmark Comparison'!C16 | D11: ='Benchmark Comparison'!D16
A14: How to use this workbook
A15: Assumptions | B15: Every rate, cap, relief and tax band. Change a blue value and the whole model updates.
A16: Benchmark Comparison | B16: Side-by-side payslip and employer cost for each benchmark, plus a custom wage (yellow cell E4).
A17: Headcount Budget | B17: Annual payroll budget for a hiring plan and the cost of moving staff up a benchmark (yellow headcounts).
A18: Wage Ladder | B18: Cost and take-home across a range of wages, with a chart (yellow start and step).
A21: Colour legend
A22: Blue text | B22: Hardcoded input you can edit
A23: Black text | B23: Formula - do not overwrite
A24: Green text | B24: Value linked from another sheet
A25: Yellow fill | B25: Scenario lever: the cells meant to be changed (example values pre-filled)
A26: Orange fill | B26: Assumption to verify against the official schedule before relying on the output
A28: Source and limits
A29: Parameters were supplied by the model author from a Belanjawan 2027 brief and have not been checked against gazetted schedules. Illustrative only; not payroll or tax advice.

Sheet Assumptions
A1: Assumptions - Belanjawan 2027 Wage Parameters
A2: Blue = editable input. Every other sheet reads from here. Orange rows are figures worth verifying against the official schedule.
A4: Parameter | B4: Value | C4: Unit | D4: Source / note
A5: Wage benchmarks
A6: National Minimum Wage | B6: 2000 | C6: RM / month | D6: Provided by user (Belanjawan 2027 brief). Effective June 2027; MSMEs under RM50m turnover temporarily exempt.
A7: Fresh Graduate & Semi-Skilled Floor | B7: 2500 | C7: RM / month | D7: Provided by user (Belanjawan 2027 brief).
A8: GLC / GLIC Living Wage Benchmark | B8: 3400 | C8: RM / month | D8: Provided by user (Belanjawan 2027 brief).
A9: Employer on-costs
A10: EPF employer rate (wage at or below threshold) | B10: 0.13 | C10: % of wage | D10: Provided by user (Belanjawan 2027 brief).
A11: EPF employer rate (wage above threshold) | B11: 0.12 | C11: % of wage | D11: Model assumption, not in the brief: current KWSP Third Schedule rate for wages above RM5,000.
A12: EPF rate threshold | B12: 5000 | C12: RM / month | D12: Provided by user (Belanjawan 2027 brief).
A13: SOCSO employer rate (Employment Injury & Invalidity) | B13: 0.0175 | C13: % of wage | D13: Provided by user (Belanjawan 2027 brief) (stated as approx. 1.75%).
A14: SOCSO employer cap | B14: 103.65 | C14: RM / month | D14: Provided by user (Belanjawan 2027 brief). Check: 1.75% x RM6,000 = RM105.00 and the current PERKESO table shows RM104.15 at the RM6,000 ceiling, so RM103.65 looks slightly low.
A15: EIS employer rate | B15: 0.002 | C15: % of wage | D15: Provided by user (Belanjawan 2027 brief).
A16: EIS employer cap | B16: 11.9 | C16: RM / month | D16: Provided by user (Belanjawan 2027 brief).
A17: SOCSO / EIS insured wage ceiling | B17: 6000 | C17: RM / month | D17: Provided by user (Belanjawan 2027 brief).
A18: HRD Corp levy rate | B18: 0.01 | C18: % of basic + fixed allowances | D18: Provided by user (Belanjawan 2027 brief).
A19: Employee deductions
A20: EPF employee rate | B20: 0.11 | C20: % of wage | D20: Provided by user (Belanjawan 2027 brief).
A21: SOCSO employee rate | B21: 0.005 | C21: % of wage | D21: Provided by user (Belanjawan 2027 brief) (stated as approx. 0.50%).
A22: SOCSO employee cap | B22: 29.65 | C22: RM / month | D22: Provided by user (Belanjawan 2027 brief). Check: 0.5% x RM6,000 = RM30.00 and the current PERKESO table shows RM29.75 at the ceiling.
A23: EIS employee rate | B23: 0.002 | C23: % of wage | D23: Provided by user (Belanjawan 2027 brief).
A24: EIS employee cap | B24: 11.9 | C24: RM / month | D24: Provided by user (Belanjawan 2027 brief).
A25: Income tax (PCB / MTD)
A26: Individual relief | B26: 12000 | C26: RM / year | D26: Provided by user (Belanjawan 2027 brief). Current statutory individual relief is RM9,000, so RM12,000 is a Belanjawan 2027 figure to confirm against the Finance Bill.
A27: EPF relief cap | B27: 4000 | C27: RM / year | D27: Model assumption, not in the brief: current LHDN cap on EPF contributions relief.
A28: Other reliefs (per employee) | B28: 0 | C28: RM / year | D28: Model assumption: zero. Add lifestyle, SOCSO, medical etc. here if needed.
A29: Individual tax rebate | B29: 400 | C29: RM / year | D29: Provided by user (Belanjawan 2027 brief).
A30: Rebate chargeable-income limit | B30: 35000 | C30: RM / year | D30: Model assumption, not in the brief: current LHDN limit for the RM400 rebate.
A32: Resident individual tax brackets | D32: Model assumption, not in the brief: current LHDN resident rates (YA 2025). Replace if Belanjawan 2027 changes the bands.
A33: Chargeable income above (RM) | B33: Marginal rate | C33: Incremental rate
A34: 0 | B34: 0 | C34: =B34
A35: 5000 | B35: 0.01 | C35: =B35-B34
A36: 20000 | B36: 0.03 | C36: =B36-B35
A37: 35000 | B37: 0.06 | C37: =B37-B36
A38: 50000 | B38: 0.11 | C38: =B38-B37
A39: 70000 | B39: 0.19 | C39: =B39-B38
A40: 100000 | B40: 0.25 | C40: =B40-B39
A41: 400000 | B41: 0.26 | C41: =B41-B40
A42: 600000 | B42: 0.28 | C42: =B42-B41
...

Sheet Benchmark Comparison
A1: Benchmark Comparison - Employer Cost and Employee Take-Home
A2: All amounts in RM per month unless stated. Yellow cell = type your own wage. Green = linked from Assumptions.
A3: Item (RM) | B3: National Minimum Wage | C3: Fresh Graduate Floor | D3: GLC / GLIC Living Wage | E3: Custom Scenario | G3: Chart data | H3: Net take-home pay | I3: Employee deductions | J3: Employer on-costs
A4: Basic monthly wage | B4: =Assumptions!$B$6 | C4: =Assumptions!$B$7 | D4: =Assumptions!$B$8 | E4: 4500 | G4: =B3 | H4: =B24 | I4: =B23 | J4: =B13
A5: Fixed cash allowances | B5: 0 | C5: 0 | D5: 0 | E5: 0 | G5: =C3 | H5: =C24 | I5: =C23 | J5: =C13
A6: Gross monthly wage | B6: =B4+B5 | C6: =C4+C5 | D6: =D4+D5 | E6: =E4+E5 | G6: =D3 | H6: =D24 | I6: =D23 | J6: =D13
G7: =E3 | H7: =E24 | I7: =E23 | J7: =E13
A8: Employer on-costs
A9: EPF (employer) | B9: =B6*IF(B6<=Assumptions!$B$12,Assumptions!$B$10,Assumptions!$B$11) | C9: =C6*IF(C6<=Assumptions!$B$12,Assumptions!$B$10,Assumptions!$B$11) | D9: =D6*IF(D6<=Assumptions!$B$12,Assumptions!$B$10,Assumptions!$B$11) | E9: =E6*IF(E6<=Assumptions!$B$12,Assumptions!$B$10,Assumptions!$B$11)
A10: SOCSO (employer) | B10: =MIN(MIN(B6,Assumptions!$B$17)*Assumptions!$B$13,Assumptions!$B$14) | C10: =MIN(MIN(C6,Assumptions!$B$17)*Assumptions!$B$13,Assumptions!$B$14) | D10: =MIN(MIN(D6,Assumptions!$B$17)*Assumptions!$B$13,Assumptions!$B$14) | E10: =MIN(MIN(E6,Assumptions!$B$17)*Assumptions!$B$13,Assumptions!$B$14)
A11: EIS (employer) | B11: =MIN(MIN(B6,Assumptions!$B$17)*Assumptions!$B$15,Assumptions!$B$16) | C11: =MIN(MIN(C6,Assumptions!$B$17)*Assumptions!$B$15,Assumptions!$B$16) | D11: =MIN(MIN(D6,Assumptions!$B$17)*Assumptions!$B$15,Assumptions!$B$16) | E11: =MIN(MIN(E6,Assumptions!$B$17)*Assumptions!$B$15,Assumptions!$B$16)
A12: HRD Corp levy | B12: =B6*Assumptions!$B$18 | C12: =C6*Assumptions!$B$18 | D12: =D6*Assumptions!$B$18 | E12: =E6*Assumptions!$B$18
A13: Total employer on-costs | B13: =SUM(B9:B12) | C13: =SUM(C9:C12) | D13: =SUM(D9:D12) | E13: =SUM(E9:E12)
A14: Fully loaded monthly cost | B14: =B6+B13 | C14: =C6+C13 | D14: =D6+D13 | E14: =E6+E13
A15: On-costs as % of gross wage | B15: =IF(B6=0,0,B13/B6) | C15: =IF(C6=0,0,C13/C6) | D15: =IF(D6=0,0,D13/D6) | E15: =IF(E6=0,0,E13/E6)
A16: Fully loaded annual cost | B16: =B14*12 | C16: =C14*12 | D16: =D14*12 | E16: =E14*12
A18: Employee deductions
A19: EPF (employee) | B19: =B6*Assumptions!$B$20 | C19: =C6*Assumptions!$B$20 | D19: =D6*Assumptions!$B$20 | E19: =E6*Assumptions!$B$20
A20: SOCSO (employee) | B20: =MIN(MIN(B6,Assumptions!$B$17)*Assumptions!$B$21,Assumptions!$B$22) | C20: =MIN(MIN(C6,Assumptions!$B$17)*Assumptions!$B$21,Assumptions!$B$22) | D20: =MIN(MIN(D6,Assumptions!$B$17)*Assumptions!$B$21,Assumptions!$B$22) | E20: =MIN(MIN(E6,Assumptions!$B$17)*Assumptions!$B$21,Assumptions!$B$22)
A21: EIS (employee) | B21: =MIN(MIN(B6,Assumptions!$B$17)*Assumptions!$B$23,Assumptions!$B$24) | C21: =MIN(MIN(C6,Assumptions!$B$17)*Assumptions!$B$23,Assumptions!$B$24) | D21: =MIN(MIN(D6,Assumptions!$B$17)*Assumptions!$B$23,Assumptions!$B$24) | E21: =MIN(MIN(E6,Assumptions!$B$17)*Assumptions!$B$23,Assumptions!$B$24)
A22: PCB / MTD | B22: =B35/12 | C22: =C35/12 | D22: =D35/12 | E22: =E35/12
A23: Total employee deductions | B23: =SUM(B19:B22) | C23: =SUM(C19:C22) | D23: =SUM(D19:D22) | E23: =SUM(E19:E22)
A24: Net take-home pay | B24: =B6-B23 | C24: =C6-C23 | D24: =D6-D23 | E24: =E6-E23
A25: Take-home as % of gross wage | B25: =IF(B6=0,0,B24/B6) | C25: =IF(C6=0,0,C24/C6) | D25: =IF(D6=0,0,D24/D6) | E25: =IF(E6=0,0,E24/E6)
A27: Annual tax computation (basis for PCB)
A28: Annual gross income | B28: =B6*12 | C28: =C6*12 | D28: =D6*12 | E28: =E6*12
A29: Less: individual relief | B29: =Assumptions!$B$26 | C29: =Assumptions!$B$26 | D29: =Assumptions!$B$26 | E29: =Assumptions!$B$26
A30: Less: EPF relief | B30: =MIN(B19*12,Assumptions!$B$27) | C30: =MIN(C19*12,Assumptions!$B$27) | D30: =MIN(D19*12,Assumptions!$B$27) | E30: =MIN(E19*12,Assumptions!$B$27)
A31: Less: other reliefs | B31: =Assumptions!$B$28 | C31: =Assumptions!$B$28 | D31: =Assumptions!$B$28 | E31: =Assumptions!$B$28
A32: Chargeable income | B32: =MAX(0,B28-B29-B30-B31) | C32: =MAX(0,C28-C29-C30-C31) | D32: =MAX(0,D28-D29-D30-D31) | E32: =MAX(0,E28-E29-E30-E31)
A33: Tax before rebate | B33: =SUMPRODUCT((B32>Assumptions!$A$34:$A$43)*(B32-Assumptions!$A$34:$A$43)*Assumptions!$C$34:$C$43) | C33: =SUMPRODUCT((C32>Assumptions!$A$34:$A$43)*(C32-Assumptions!$A$34:$A$43)*Assumptions!$C$34:$C$43) | D33: =SUMPRODUCT((D32>Assumptions!$A$34:$A$43)*(D32-Assumptions!$A$34:$A$43)*Assumptions!$C$34:$C$43) | E33: =SUMPRODUCT((E32>Assumptions!$A$34:$A$43)*(E32-Assumptions!$A$34:$A$43)*Assumptions!$C$34:$C$43)
A34: Less: rebate | B34: =IF(B32<=Assumptions!$B$30,MIN(B33,Assumptions!$B$29),0) | C34: =IF(C32<=Assumptions!$B$30,MIN(C33,Assumptions!$B$29),0) | D34: =IF(D32<=Assumptions!$B$30,MIN(D33,Assumptions!$B$29),0) | E34: =IF(E32<=Assumptions!$B$30,MIN(E33,Assumptions!$B$29),0)
A35: Annual tax payable | B35: =B33-B34 | C35: =C33-C34 | D35: =D33-D34 | E35: =E33-E34
A37: Difference vs Fresh Graduate Floor
A38: Fully loaded monthly cost vs floor | B38: =B14-$C$14 | C38: =C14-$C$14 | D38: =D14-$C$14 | E38: =E14-$C$14
A39: Net take-home pay vs floor | B39: =B24-$C$24 | C39: =C24-$C$24 | D39: =D24-$C$24 | E39: =E24-$C$24
A40: Fully loaded annual cost vs floor | B40: =B16-$C$16 | C40: =C16-$C$16 | D40: =D16-$C$16 | E40: =E16-$C$16
A42: Allowances default to zero; enter fixed cash allowances in row 5 to include them in every statutory base.

Sheet Headcount Budget
A1: Headcount Budget - Annual Cost of a Hiring Plan
A2: Blue headcounts are example values; overwrite them with your own plan. Wages and per-head costs link to Benchmark Comparison.
A4: Tier | B4: Gross monthly wage (RM) | C4: Headcount | D4: Loaded cost per head / month (RM) | E4: Monthly payroll cost (RM) | F4: Annual payroll cost (RM) | G4: Annual statutory on-costs (RM) | H4: Net take-home per head / month (RM)
A5: National Minimum Wage | B5: ='Benchmark Comparison'!B6 | C5: 10 | D5: ='Benchmark Comparison'!B14 | E5: =C5*D5 | F5: =E5*12 | G5: =C5*'Benchmark Comparison'!B13*12 | H5: ='Benchmark Comparison'!B24
A6: Fresh Graduate Floor | B6: ='Benchmark Comparison'!C6 | C6: 15 | D6: ='Benchmark Comparison'!C14 | E6: =C6*D6 | F6: =E6*12 | G6: =C6*'Benchmark Comparison'!C13*12 | H6: ='Benchmark Comparison'!C24
A7: GLC / GLIC Living Wage | B7: ='Benchmark Comparison'!D6 | C7: 5 | D7: ='Benchmark Comparison'!D14 | E7: =C7*D7 | F7: =E7*12 | G7: =C7*'Benchmark Comparison'!D13*12 | H7: ='Benchmark Comparison'!D24
A8: Custom Scenario | B8: ='Benchmark Comparison'!E6 | C8: 2 | D8: ='Benchmark Comparison'!E14 | E8: =C8*D8 | F8: =E8*12 | G8: =C8*'Benchmark Comparison'!E13*12 | H8: ='Benchmark Comparison'!E24
A9: Total | B9: Average loaded cost per head: | C9: =SUM(C5:C8) | D9: =IF(C9=0,0,E9/C9) | E9: =SUM(E5:E8) | F9: =SUM(F5:F8) | G9: =SUM(G5:G8)
A10: On-costs as % of total annual payroll cost | G10: =IF(F9=0,0,G9/F9)
A13: Wage uplift analysis
A14: What it costs the employer, and what the employee gains, when staff move up a benchmark.
A15: Uplift | B15: Wage increase per head / month (RM) | C15: Staff affected | D15: Extra loaded cost per head / month (RM) | E15: Extra monthly cost (RM) | F15: Extra annual cost (RM) | G15: Employer cost per RM1 of extra take-home (RM) | H15: Extra take-home per head / month (RM)
A16: Minimum Wage to Fresh Graduate Floor | B16: ='Benchmark Comparison'!C6-'Benchmark Comparison'!B6 | C16: 10 | D16: ='Benchmark Comparison'!C14-'Benchmark Comparison'!B14 | E16: =C16*D16 | F16: =E16*12 | G16: =IF(H16=0,0,D16/H16) | H16: ='Benchmark Comparison'!C24-'Benchmark Comparison'!B24
A17: Fresh Graduate Floor to GLC Living Wage | B17: ='Benchmark Comparison'!D6-'Benchmark Comparison'!C6 | C17: 15 | D17: ='Benchmark Comparison'!D14-'Benchmark Comparison'!C14 | E17: =C17*D17 | F17: =E17*12 | G17: =IF(H17=0,0,D17/H17) | H17: ='Benchmark Comparison'!D24-'Benchmark Comparison'!C24
A18: Minimum Wage to GLC Living Wage | B18: ='Benchmark Comparison'!D6-'Benchmark Comparison'!B6 | C18: 10 | D18: ='Benchmark Comparison'!D14-'Benchmark Comparison'!B14 | E18: =C18*D18 | F18: =E18*12 | G18: =IF(H18=0,0,D18/H18) | H18: ='Benchmark Comparison'!D24-'Benchmark Comparison'!B24
A20: Each uplift row is independent; the three rows are alternatives, not a sum.

Sheet Wage Ladder
A1: Wage Ladder - Sensitivity of Cost and Take-Home to Monthly Wage
A2: Change the starting wage or step (yellow) to redraw the ladder and chart.
A3: Starting wage (RM) | B3: 2000 | C3: Step (RM) | D3: 250
A5: Gross monthly wage (RM) | B5: EPF employer | C5: SOCSO employer | D5: EIS employer | E5: HRD levy | F5: Total on-costs | G5: Fully loaded cost | H5: On-cost % | I5: EPF employee | J5: SOCSO employee | K5: EIS employee | L5: Chargeable income (annual) | M5: Tax payable (annual) | N5: PCB / month | O5: Net take-home pay | P5: Take-home %
A6: =$B$3 | B6: =$A6*IF($A6<=Assumptions!$B$12,Assumptions!$B$10,Assumptions!$B$11) | C6: =MIN(MIN($A6,Assumptions!$B$17)*Assumptions!$B$13,Assumptions!$B$14) | D6: =MIN(MIN($A6,Assumptions!$B$17)*Assumptions!$B$15,Assumptions!$B$16) | E6: =$A6*Assumptions!$B$18 | F6: =SUM(B6:E6) | G6: =A6+F6 | H6: =IF(A6=0,0,F6/A6) | I6: =$A6*Assumptions!$B$20 | J6: =MIN(MIN($A6,Assumptions!$B$17)*Assumptions!$B$21,Assumptions!$B$22) | K6: =MIN(MIN($A6,Assumptions!$B$17)*Assumptions!$B$23,Assumptions!$B$24) | L6: =MAX(0,A6*12-Assumptions!$B$26-MIN(I6*12,Assumptions!$B$27)-Assumptions!$B$28) | M6: =SUMPRODUCT((L6>Assumptions!$A$34:$A$43)*(L6-Assumptions!$A$34:$A$43)*Assumptions!$C$34:$C$43)-IF(L6<=Assumptions!$B$30,MIN(SUMPRODUCT((L6>Assumptions!$A$34:$A$43)*(L6-Assumptions!$A$34:$A$43)*Assumptions!$C$34:$C$43),Assumptions!$B$29),0) | N6: =M6/12 | O6: =A6-I6-J6-K6-N6 | P6: =IF(A6=0,0,O6/A6)
A7: =A6+$D$3 | B7: =$A7*IF($A7<=Assumptions!$B$12,Assumptions!$B$10,Assumptions!$B$11) | C7: =MIN(MIN($A7,Assumptions!$B$17)*Assumptions!$B$13,Assumptions!$B$14) | D7: =MIN(MIN($A7,Assumptions!$B$17)*Assumptions!$B$15,Assumptions!$B$16) | E7: =$A7*Assumptions!$B$18 | F7: =SUM(B7:E7) | G7: =A7+F7 | H7: =IF(A7=0,0,F7/A7) | I7: =$A7*Assumptions!$B$20 | J7: =MIN(MIN($A7,Assumptions!$B$17)*Assumptions!$B$21,Assumptions!$B$22) | K7: =MIN(MIN($A7,Assumptions!$B$17)*Assumptions!$B$23,Assumptions!$B$24) | L7: =MAX(0,A7*12-Assumptions!$B$26-MIN(I7*12,Assumptions!$B$27)-Assumptions!$B$28) | M7: =SUMPRODUCT((L7>Assumptions!$A$34:$A$43)*(L7-Assumptions!$A$34:$A$43)*Assumptions!$C$34:$C$43)-IF(L7<=Assumptions!$B$30,MIN(SUMPRODUCT((L7>Assumptions!$A$34:$A$43)*(L7-Assumptions!$A$34:$A$43)*Assumptions!$C$34:$C$43),Assumptions!$B$29),0) | N7: =M7/12 | O7: =A7-I7-J7-K7-N7 | P7: =IF(A7=0,0,O7/A7)
A8: =A7+$D$3 | B8: =$A8*IF($A8<=Assumptions!$B$12,Assumptions!$B$10,Assumptions!$B$11) | C8: =MIN(MIN($A8,Assumptions!$B$17)*Assumptions!$B$13,Assumptions!$B$14) | D8: =MIN(MIN($A8,Assumptions!$B$17)*Assumptions!$B$15,Assumptions!$B$16) | E8: =$A8*Assumptions!$B$18 | F8: =SUM(B8:E8) | G8: =A8+F8 | H8: =IF(A8=0,0,F8/A8) | I8: =$A8*Assumptions!$B$20 | J8: =MIN(MIN($A8,Assumptions!$B$17)*Assumptions!$B$21,Assumptions!$B$22) | K8: =MIN(MIN($A8,Assumptions!$B$17)*Assumptions!$B$23,Assumptions!$B$24) | L8: =MAX(0,A8*12-Assumptions!$B$26-MIN(I8*12,Assumptions!$B$27)-Assumptions!$B$28) | M8: =SUMPRODUCT((L8>Assumptions!$A$34:$A$43)*(L8-Assumptions!$A$34:$A$43)*Assumptions!$C$34:$C$43)-IF(L8<=Assumptions!$B$30,MIN(SUMPRODUCT((L8>Assumptions!$A$34:$A$43)*(L8-Assumptions!$A$34:$A$43)*Assumptions!$C$34:$C$43),Assumptions!$B$29),0) | N8: =M8/12 | O8: =A8-I8-J8-K8-N8 | P8: =IF(A8=0,0,O8/A8)
A9: =A8+$D$3 | B9: =$A9*IF($A9<=Assumptions!$B$12,Assumptions!$B$10,Assumptions!$B$11) | C9: =MIN(MIN($A9,Assumptions!$B$17)*Assumptions!$B$13,Assumptions!$B$14) | D9: =MIN(MIN($A9,Assumptions!$B$17)*Assumptions!$B$15,Assumptions!$B$16) | E9: =$A9*Assumptions!$B$18 | F9: =SUM(B9:E9) | G9: =A9+F9 | H9: =IF(A9=0,0,F9/A9) | I9: =$A9*Assumptions!$B$20 | J9: =MIN(MIN($A9,Assumptions!$B$17)*Assumptions!$B$21,Assumptions!$B$22) | K9: =MIN(MIN($A9,Assumptions!$B$17)*Assumptions!$B$23,Assumptions!$B$24) | L9: =MAX(0,A9*12-Assumptions!$B$26-MIN(I9*12,Assumptions!$B$27)-Assumptions!$B$28) | M9: =SUMPRODUCT((L9>Assumptions!$A$34:$A$43)*(L9-Assumptions!$A$34:$A$43)*Assumptions!$C$34:$C$43)-IF(L9<=Assumptions!$B$30,MIN(SUMPRODUCT((L9>Assumptions!$A$34:$A$43)*(L9-Assumptions!$A$34:$A$43)*Assumptions!$C$34:$C$43),Assumptions!$B$29),0) | N9: =M9/12 | O9: =A9-I9-J9-K9-N9 | P9: =IF(A9=0,0,O9/A9)
A10: =A9+$D$3 | B10: =$A10*IF($A10<=Assumptions!$B$12,Assumptions!$B$10,Assumptions!$B$11) | C10: =MIN(MIN($A10,Assumptions!$B$17)*Assumptions!$B$13,Assumptions!$B$14) | D10: =MIN(MIN($A10,Assumptions!$B$17)*Assumptions!$B$15,Assumptions!$B$16) | E10: =$A10*Assumptions!$B$18 | F10: =SUM(B10:E10) | G10: =A10+F10 | H10: =IF(A10=0,0,F10/A10) | I10: =$A10*Assumptions!$B$20 | J10: =MIN(MIN($A10,Assumptions!$B$17)*Assumptions!$B$21,Assumptions!$B$22) | K10: =MIN(MIN($A10,Assumptions!$B$17)*Assumptions!$B$23,Assumptions!$B$24) | L10: =MAX(0,A10*12-Assumptions!$B$26-MIN(I10*12,Assumptions!$B$27)-Assumptions!$B$28) | M10: =SUMPRODUCT((L10>Assumptions!$A$34:$A$43)*(L10-Assumptions!$A$34:$A$43)*Assumptions!$C$34:$C$43)-IF(L10<=Assumptions!$B$30,MIN(SUMPRODUCT((L10>Assumptions!$A$34:$A$43)*(L10-Assumptions!$A$34:$A$43)*Assumptions!$C$34:$C$43),Assumptions!$B$29),0) | N10: =M10/12 | O10: =A10-I10-J10-K10-N10 | P10: =IF(A10=0,0,O10/A10)
A11: =A10+$D$3 | B11: =$A11*IF($A11<=Assumptions!$B$12,Assumptions!$B$10,Assumptions!$B$11) | C11: =MIN(MIN($A11,Assumptions!$B$17)*Assumptions!$B$13,Assumptions!$B$14) | D11: =MIN(MIN($A11,Assumptions!$B$17)*Assumptions!$B$15,Assumptions!$B$16) | E11: =$A11*Assumptions!$B$18 | F11: =SUM(B11:E11) | G11: =A11+F11 | H11: =IF(A11=0,0,F11/A11) | I11: =$A11*Assumptions!$B$20 | J11: =MIN(MIN($A11,Assumptions!$B$17)*Assumptions!$B$21,Assumptions!$B$22) | K11: =MIN(MIN($A11,Assumptions!$B$17)*Assumptions!$B$23,Assumptions!$B$24) | L11: =MAX(0,A11*12-Assumptions!$B$26-MIN(I11*12,Assumptions!$B$27)-Assumptions!$B$28) | M11: =SUMPRODUCT((L11>Assumptions!$A$34:$A$43)*(L11-Assumptions!$A$34:$A$43)*Assumptions!$C$34:$C$43)-IF(L11<=Assumptions!$B$30,MIN(SUMPRODUCT((L11>Assumptions!$A$34:$A$43)*(L11-Assumptions!$A$34:$A$43)*Assumptions!$C$34:$C$43),Assumptions!$B$29),0) | N11: =M11/12 | O11: =A11-I11-J11-K11-N11 | P11: =IF(A11=0,0,O11/A11)
A12: =A11+$D$3 | B12: =$A12*IF($A12<=Assumptions!$B$12,Assumptions!$B$10,Assumptions!$B$11) | C12: =MIN(MIN($A12,Assumptions!$B$17)*Assumptions!$B$13,Assumptions!$B$14) | D12: =MIN(MIN($A12,Assumptions!$B$17)*Assumptions!$B$15,Assumptions!$B$16) | E12: =$A12*Assumptions!$B$18 | F12: =SUM(B12:E12) | G12: =A12+F12 | H12: =IF(A12=0,0,F12/A12) | I12: =$A12*Assumptions!$B$20 | J12: =MIN(MIN($A12,Assumptions!$B$17)*Assumptions!$B$21,Assumptions!$B$22) | K12: =MIN(MIN($A12,Assumptions!$B$17)*Assumptions!$B$23,Assumptions!$B$24) | L12: =MAX(0,A12*12-Assumptions!$B$26-MIN(I12*12,Assumptions!$B$27)-Assumptions!$B$28) | M12: =SUMPRODUCT((L12>Assumptions!$A$34:$A$43)*(L12-Assumptions!$A$34:$A$43)*Assumptions!$C$34:$C$43)-IF(L12<=Assumptions!$B$30,MIN(SUMPRODUCT((L12>Assumptions!$A$34:$A$43)*(L12-Assumptions!$A$34:$A$43)*Assumptions!$C$34:$C$43),Assumptions!$B$29),0) | N12: =M12/12 | O12: =A12-I12-J12-K12-N12 | P12: =IF(A12=0,0,O12/A12)
A13: =A12+$D$3 | B13: =$A13*IF($A13<=Assumptions!$B$12,Assumptions!$B$10,Assumptions!$B$11) | C13: =MIN(MIN($A13,Assumptions!$B$17)*Assumptions!$B$13,Assumptions!$B$14) | D13: =MIN(MIN($A13,Assumptions!$B$17)*Assumptions!$B$15,Assumptions!$B$16) | E13: =$A13*Assumptions!$B$18 | F13: =SUM(B13:E13) | G13: =A13+F13 | H13: =IF(A13=0,0,F13/A13) | I13: =$A13*Assumptions!$B$20 | J13: =MIN(MIN($A13,Assumptions!$B$17)*Assumptions!$B$21,Assumptions!$B$22) | K13: =MIN(MIN($A13,Assumptions!$B$17)*Assumptions!$B$23,Assumptions!$B$24) | L13: =MAX(0,A13*12-Assumptions!$B$26-MIN(I13*12,Assumptions!$B$27)-Assumptions!$B$28) | M13: =SUMPRODUCT((L13>Assumptions!$A$34:$A$43)*(L13-Assumptions!$A$34:$A$43)*Assumptions!$C$34:$C$43)-IF(L13<=Assumptions!$B$30,MIN(SUMPRODUCT((L13>Assumptions!$A$34:$A$43)*(L13-Assumptions!$A$34:$A$43)*Assumptions!$C$34:$C$43),Assumptions!$B$29),0) | N13: =M13/12 | O13: =A13-I13-J13-K13-N13 | P13: =IF(A13=0,0,O13/A13)
A14: =A13+$D$3 | B14: =$A14*IF($A14<=Assumptions!$B$12,Assumptions!$B$10,Assumptions!$B$11) | C14: =MIN(MIN($A14,Assumptions!$B$17)*Assumptions!$B$13,Assumptions!$B$14) | D14: =MIN(MIN($A14,Assumptions!$B$17)*Assumptions!$B$15,Assumptions!$B$16) | E14: =$A14*Assumptions!$B$18 | F14: =SUM(B14:E14) | G14: =A14+F14 | H14: =IF(A14=0,0,F14/A14) | I14: =$A14*Assumptions!$B$20 | J14: =MIN(MIN($A14,Assumptions!$B$17)*Assumptions!$B$21,Assumptions!$B$22) | K14: =MIN(MIN($A14,Assumptions!$B$17)*Assumptions!$B$23,Assumptions!$B$24) | L14: =MAX(0,A14*12-Assumptions!$B$26-MIN(I14*12,Assumptions!$B$27)-Assumptions!$B$28) | M14: =SUMPRODUCT((L14>Assumptions!$A$34:$A$43)*(L14-Assumptions!$A$34:$A$43)*Assumptions!$C$34:$C$43)-IF(L14<=Assumptions!$B$30,MIN(SUMPRODUCT((L14>Assumptions!$A$34:$A$43)*(L14-Assumptions!$A$34:$A$43)*Assumptions!$C$34:$C$43),Assumptions!$B$29),0) | N14: =M14/12 | O14: =A14-I14-J14-K14-N14 | P14: =IF(A14=0,0,O14/A14)
A15: =A14+$D$3 | B15: =$A15*IF($A15<=Assumptions!$B$12,Assumptions!$B$10,Assumptions!$B$11) | C15: =MIN(MIN($A15,Assumptions!$B$17)*Assumptions!$B$13,Assumptions!$B$14) | D15: =MIN(MIN($A15,Assumptions!$B$17)*Assumptions!$B$15,Assumptions!$B$16) | E15: =$A15*Assumptions!$B$18 | F15: =SUM(B15:E15) | G15: =A15+F15 | H15: =IF(A15=0,0,F15/A15) | I15: =$A15*Assumptions!$B$20 | J15: =MIN(MIN($A15,Assumptions!$B$17)*Assumptions!$B$21,Assumptions!$B$22) | K15: =MIN(MIN($A15,Assumptions!$B$17)*Assumptions!$B$23,Assumptions!$B$24) | L15: =MAX(0,A15*12-Assumptions!$B$26-MIN(I15*12,Assumptions!$B$27)-Assumptions!$B$28) | M15: =SUMPRODUCT((L15>Assumptions!$A$34:$A$43)*(L15-Assumptions!$A$34:$A$43)*Assumptions!$C$34:$C$43)-IF(L15<=Assumptions!$B$30,MIN(SUMPRODUCT((L15>Assumptions!$A$34:$A$43)*(L15-Assumptions!$A$34:$A$43)*Assumptions!$C$34:$C$43),Assumptions!$B$29),0) | N15: =M15/12 | O15: =A15-I15-J15-K15-N15 | P15: =IF(A15=0,0,O15/A15)
A16: =A15+$D$3 | B16: =$A16*IF($A16<=Assumptions!$B$12,Assumptions!$B$10,Assumptions!$B$11) | C16: =MIN(MIN($A16,Assumptions!$B$17)*Assumptions!$B$13,Assumptions!$B$14) | D16: =MIN(MIN($A16,Assumptions!$B$17)*Assumptions!$B$15,Assumptions!$B$16) | E16: =$A16*Assumptions!$B$18 | F16: =SUM(B16:E16) | G16: =A16+F16 | H16: =IF(A16=0,0,F16/A16) | I16: =$A16*Assumptions!$B$20 | J16: =MIN(MIN($A16,Assumptions!$B$17)*Assumptions!$B$21,Assumptions!$B$22) | K16: =MIN(MIN($A16,Assumptions!$B$17)*Assumptions!$B$23,Assumptions!$B$24) | L16: =MAX(0,A16*12-Assumptions!$B$26-MIN(I16*12,Assumptions!$B$27)-Assumptions!$B$28) | M16: =SUMPRODUCT((L16>Assumptions!$A$34:$A$43)*(L16-Assumptions!$A$34:$A$43)*Assumptions!$C$34:$C$43)-IF(L16<=Assumptions!$B$30,MIN(SUMPRODUCT((L16>Assumptions!$A$34:$A$43)*(L16-Assumptions!$A$34:$A$43)*Assumptions!$C$34:$C$43),Assumptions!$B$29),0) | N16: =M16/12 | O16: =A16-I16-J16-K16-N16 | P16: =IF(A16=0,0,O16/A16)
A17: =A16+$D$3 | B17: =$A17*IF($A17<=Assumptions!$B$12,Assumptions!$B$10,Assumptions!$B$11) | C17: =MIN(MIN($A17,Assumptions!$B$17)*Assumptions!$B$13,Assumptions!$B$14) | D17: =MIN(MIN($A17,Assumptions!$B$17)*Assumptions!$B$15,Assumptions!$B$16) | E17: =$A17*Assumptions!$B$18 | F17: =SUM(B17:E17) | G17: =A17+F17 | H17: =IF(A17=0,0,F17/A17) | I17: =$A17*Assumptions!$B$20 | J17: =MIN(MIN($A17,Assumptions!$B$17)*Assumptions!$B$21,Assumptions!$B$22) | K17: =MIN(MIN($A17,Assumptions!$B$17)*Assumptions!$B$23,Assumptions!$B$24) | L17: =MAX(0,A17*12-Assumptions!$B$26-MIN(I17*12,Assumptions!$B$27)-Assumptions!$B$28) | M17: =SUMPRODUCT((L17>Assumptions!$A$34:$A$43)*(L17-Assumptions!$A$34:$A$43)*Assumptions!$C$34:$C$43)-IF(L17<=Assumptions!$B$30,MIN(SUMPRODUCT((L17>Assumptions!$A$34:$A$43)*(L17-Assumptions!$A$34:$A$43)*Assumptions!$C$34:$C$43),Assumptions!$B$29),0) | N17: =M17/12 | O17: =A17-I17-J17-K17-N17 | P17: =IF(A17=0,0,O17/A17)
A18: =A17+$D$3 | B18: =$A18*IF($A18<=Assumptions!$B$12,Assumptions!$B$10,Assumptions!$B$11) | C18: =MIN(MIN($A18,Assumptions!$B$17)*Assumptions!$B$13,Assumptions!$B$14) | D18: =MIN(MIN($A18,Assumptions!$B$17)*Assumptions!$B$15,Assumptions!$B$16) | E18: =$A18*Assumptions!$B$18 | F18: =SUM(B18:E18) | G18: =A18+F18 | H18: =IF(A18=0,0,F18/A18) | I18: =$A18*Assumptions!$B$20 | J18: =MIN(MIN($A18,Assumptions!$B$17)*Assumptions!$B$21,Assumptions!$B$22) | K18: =MIN(MIN($A18,Assumptions!$B$17)*Assumptions!$B$23,Assumptions!$B$24) | L18: =MAX(0,A18*12-Assumptions!$B$26-MIN(I18*12,Assumptions!$B$27)-Assumptions!$B$28) | M18: =SUMPRODUCT((L18>Assumptions!$A$34:$A$43)*(L18-Assumptions!$A$34:$A$43)*Assumptions!$C$34:$C$43)-IF(L18<=Assumptions!$B$30,MIN(SUMPRODUCT((L18>Assumptions!$A$34:$A$43)*(L18-Assumptions!$A$34:$A$43)*Assumptions!$C$34:$C$43),Assumptions!$B$29),0) | N18: =M18/12 | O18: =A18-I18-J18-K18-N18 | P18: =IF(A18=0,0,O18/A18)
... A22: =A21+$D$3 | B22: =$A22*IF($A22<=Assumptions!$B$12,Assumptions!$B$10,Assumptions!$B$11) | C22: =MIN(MIN($A22,Assumptions!$B$17)*Assumptions!$B$13,Assumptions!$B$14) | D22: =MIN(MIN($A22,Assumptions!$B$17)*Assumptions!$B$15,Assumptions!$B$16) | E22: =$A22*Assumptions!$B$18 | F22: =SUM(B22:E22) | G22: =A22+F22 | H22: =IF(A22=0,0,F22/A22) | I22: =$A22*Assumptions!$B$20 | J22: =MIN(MIN($A22,Assumptions!$B$17)*Assumptions!$B$21,Assumptions!$B$22) | K22: =MIN(MIN($A22,Assumptions!$B$17)*Assumptions!$B$23,Assumptions!$B$24) | L22: =MAX(0,A22*12-Assumptions!$B$26-MIN(I22*12,Assumptions!$B$27)-Assumptions!$B$28) | M22: =SUMPRODUCT((L22>Assumptions!$A$34:$A$43)*(L22-Assumptions!$A$34:$A$43)*Assumptions!$C$34:$C$43)-IF(L22<=Assumptions!$B$30,MIN(SUMPRODUCT((L22>Assumptions!$A$34:$A$43)*(L22-Assumptions!$A$34:$A$43)*Assumptions!$C$34:$C$43),Assumptions!$B$29),0) | N22: =M22/12 | O22: =A22-I22-J22-K22-N22 | P22: =IF(A22=0,0,O22/A22)
